<?xml version="1.0" ?>
<!-- =================================================================================== -->
<!-- |    This document was autogenerated by xacro from gen3_robotiq_2f_85.xacro       | -->
<!-- |    EDITING THIS FILE BY HAND IS NOT RECOMMENDED                                 | -->
<!-- =================================================================================== -->
<robot name="gen3_robotiq_2f_85">
  <!-- Run the macros -->
  <link name="base">
    <inertial>
      <origin rpy="0 0 0" xyz="-0.000648 -0.000166 0.084487"/>
      <mass value="1.697"/>
      <inertia ixx="0.004622" ixy="9E-06" ixz="6E-05" iyy="0.004495" iyz="9E-06" izz="0.002079"/>
    </inertial>
    <visual>
      <origin rpy="0 0 0" xyz="0 0 0"/>
      <geometry>
        <mesh filename="meshes/base_link.obj"/>
      </geometry>
      <material name="">
        <color rgba="0.64 0.64 0.64 1"/>
      </material>
    </visual>
    <collision>
      <origin rpy="0 0 0" xyz="0 0 0"/>
      <geometry>
        <mesh filename="meshes/base_link.obj"/>
      </geometry>
    </collision>
  </link>

  <link name="shoulder_link">
    <inertial>
      <origin rpy="0 0 0" xyz="-2.3E-05 -0.010364 -0.07336"/>
      <mass value="1.3773"/>
      <inertia ixx="0.00457" ixy="1E-06" ixz="2E-06" iyy="0.004831" iyz="0.000448" izz="0.001409"/>
    </inertial>
    <visual>
      <origin rpy="0 0 0" xyz="0 0 0"/>
      <geometry>
        <mesh filename="meshes/shoulder_link.obj"/>
      </geometry>
      <material name="">
        <color rgba="0.64 0.64 0.64 1"/>
      </material>
    </visual>
    <collision>
      <origin rpy="0 0 0" xyz="0 0 0"/>
      <geometry>
        <mesh filename="meshes/shoulder_link.obj"/>
      </geometry>
    </collision>
  </link>

  <joint name="joint_1" type="continuous">
    <origin rpy="3.1416 2.7629E-18 -4.9305E-36" xyz="0 0 0.15643"/>
    <parent link="base"/>
    <child link="shoulder_link"/>
    <axis xyz="0 0 1"/>
    <limit effort="39" velocity="1.3963"/>
  </joint>

  <link name="half_arm_1_link">
    <inertial>
      <origin rpy="0 0 0" xyz="-4.4E-05 -0.09958 -0.013278"/>
      <mass value="1.1636"/>
      <inertia ixx="0.011088" ixy="5E-06" ixz="0" iyy="0.001072" iyz="-0.000691" izz="0.011255"/>
    </inertial>
    <visual>
      <origin rpy="0 0 0" xyz="0 0 0"/>
      <geometry>
        <mesh filename="meshes/half_arm_1_link.obj"/>
      </geometry>
      <material name="">
        <color rgba="0.64 0.64 0.64 1"/>
      </material>
    </visual>
    <collision>
      <origin rpy="0 0 0" xyz="0 0 0"/>
      <geometry>
        <mesh filename="meshes/half_arm_1_link.obj"/>
      </geometry>
    </collision>
  </link>

  <joint name="joint_2" type="revolute">
    <origin rpy="1.5708 2.1343E-17 -1.1102E-16" xyz="0 0.005375 -0.12838"/>
    <parent link="shoulder_link"/>
    <child link="half_arm_1_link"/>
    <axis xyz="0 0 1"/>
    <limit effort="39" lower="-2.41" upper="2.41" velocity="1.3963"/>
  </joint>

  <link name="half_arm_2_link">
    <inertial>
      <origin rpy="0 0 0" xyz="-4.4E-05 -0.006641 -0.117892"/>
      <mass value="1.1636"/>
      <inertia ixx="0.010932" ixy="0" ixz="-7E-06" iyy="0.011127" iyz="0.000606" izz="0.001043"/>
    </inertial>
    <visual>
      <origin rpy="0 0 0" xyz="0 0 0"/>
      <geometry>
        <mesh filename="meshes/half_arm_2_link.obj"/>
      </geometry>
      <material name="">
        <color rgba="0.64 0.64 0.64 1"/>
      </material>
    </visual>
    <collision>
      <origin rpy="0 0 0" xyz="0 0 0"/>
      <geometry>
        <mesh filename="meshes/half_arm_2_link.obj"/>
      </geometry>
    </collision>
  </link>

  <joint name="joint_3" type="continuous">
    <origin rpy="-1.5708 1.2326E-32 -2.9122E-16" xyz="0 -0.21038 -0.006375"/>
    <parent link="half_arm_1_link"/>
    <child link="half_arm_2_link"/>
    <axis xyz="0 0 1"/>
    <limit effort="39" velocity="1.3963"/>
  </joint>

  <link name="forearm_link">
    <inertial>
      <origin rpy="0 0 0" xyz="-1.8E-05 -0.075478 -0.015006"/>
      <mass value="0.9302"/>
      <inertia ixx="0.008147" ixy="-1E-06" ixz="0" iyy="0.000631" iyz="-0.0005" izz="0.008316"/>
    </inertial>
    <visual>
      <origin rpy="0 0 0" xyz="0 0 0"/>
      <geometry>
        <mesh filename="meshes/forearm_link.obj"/>
      </geometry>
      <material name="">
        <color rgba="0.64 0.64 0.64 1"/>
      </material>
    </visual>
    <collision>
      <origin rpy="0 0 0" xyz="0 0 0"/>
      <geometry>
        <mesh filename="meshes/forearm_link.obj"/>
      </geometry>
    </collision>
  </link>

  <joint name="joint_4" type="revolute">
    <origin rpy="1.5708 -6.6954E-17 -1.6653E-16" xyz="0 0.006375 -0.21038"/>
    <parent link="half_arm_2_link"/>
    <child link="forearm_link"/>
    <axis xyz="0 0 1"/>
    <limit effort="39" lower="-2.66" upper="2.66" velocity="1.3963"/>
  </joint>

  <link name="spherical_wrist_1_link">
    <inertial>
      <origin rpy="0 0 0" xyz="1E-06 -0.009432 -0.063883"/>
      <mass value="0.6781"/>
      <inertia ixx="0.001596" ixy="0" ixz="0" iyy="0.001607" iyz="0.000256" izz="0.000399"/>
    </inertial>
    <visual>
      <origin rpy="0 0 0" xyz="0 0 0"/>
      <geometry>
        <mesh filename="meshes/spherical_wrist_1_link.obj"/>
      </geometry>
      <material name="">
        <color rgba="0.64 0.64 0.64 1"/>
      </material>
    </visual>
    <collision>
      <origin rpy="0 0 0" xyz="0 0 0"/>
      <geometry>
        <mesh filename="meshes/spherical_wrist_1_link.obj"/>
      </geometry>
    </collision>
  </link>

  <joint name="joint_5" type="continuous">
    <origin rpy="-1.5708 2.2204E-16 -6.373E-17" xyz="0 -0.20843 -0.006375"/>
    <parent link="forearm_link"/>
    <child link="spherical_wrist_1_link"/>
    <axis xyz="0 0 1"/>
    <limit effort="9" velocity="1.2218"/>
  </joint>

  <link name="spherical_wrist_2_link">
    <inertial>
      <origin rpy="0 0 0" xyz="1E-06 -0.045483 -0.00965"/>
      <mass value="0.6781"/>
      <inertia ixx="0.001641" ixy="0" ixz="0" iyy="0.00041" iyz="-0.000278" izz="0.001641"/>
    </inertial>
    <visual>
      <origin rpy="0 0 0" xyz="0 0 0"/>
      <geometry>
        <mesh filename="meshes/spherical_wrist_2_link.obj"/>
      </geometry>
      <material name="">
        <color rgba="0.64 0.64 0.64 1"/>
      </material>
    </visual>
    <collision>
      <origin rpy="0 0 0" xyz="0 0 0"/>
      <geometry>
        <mesh filename="meshes/spherical_wrist_2_link.obj"/>
      </geometry>
    </collision>
  </link>

  <joint name="joint_6" type="revolute">
    <origin rpy="1.5708 9.2076E-28 -8.2157E-15" xyz="0 0.00017505 -0.10593"/>
    <parent link="spherical_wrist_1_link"/>
    <child link="spherical_wrist_2_link"/>
    <axis xyz="0 0 1"/>
    <limit effort="9" lower="-2.23" upper="2.23" velocity="1.2218"/>
  </joint>

  <link name="bracelet_link">
    <inertial>
      <!-- This is different from the documentation -->
      <origin rpy="0 0 0" xyz="0.000281 0.011402 -0.029798"/>
      <mass value="0.5"/>
      <inertia ixx="0.000587" ixy="3E-06" ixz="3E-06" iyy="0.000369" iyz="-0.000118" izz="0.000609"/>
    </inertial>
    <visual>
      <origin rpy="0 0 0" xyz="0 0 0"/>
      <geometry>
        <mesh filename="meshes/bracelet_with_vision_link.obj"/>
      </geometry>
      <material name="">
        <color rgba="0.64 0.64 0.64 1"/>
      </material>
    </visual>
    <collision>
      <origin rpy="0 0 0" xyz="0 0 0"/>
      <geometry>
        <mesh filename="meshes/bracelet_with_vision_link.obj"/>
      </geometry>
    </collision>
  </link>

  <joint name="joint_7" type="continuous">
    <origin rpy="-1.5708 -5.5511E-17 9.6396E-17" xyz="0 -0.10593 -0.00017505"/>
    <parent link="spherical_wrist_2_link"/>
    <child link="bracelet_link"/>
    <axis xyz="0 0 1"/>
    <limit effort="9" velocity="1.2218"/>
  </joint>

  <!-- gripper code -->


  <joint name="gripper_base_joint" type="fixed">
    <!--
    <parent link="end_effector_link"/>
  -->
    <parent link="bracelet_link"/>
    <child link="gripper_base"/>
    <origin rpy="1.5707 0.0 0.0" xyz="0.0 0.0 -0.0615250000000001"/>
    <!-- 1.57 -->
  </joint>

  <link name="gripper_base">
    <inertial>
      <origin rpy="0 0 0" xyz="6.91E-06 4.4117E-06 0.031656"/>
      <mass value="0.60831"/>
      <inertia ixx="0.0004596" ixy="1.5559E-09" ixz="1.397E-07" iyy="0.0005181" iyz="-1.0325E-11" izz="0.00036051"/>
    </inertial>
    <visual>
      <origin rpy="0 0 0" xyz="0 0 0"/>
      <geometry>
        <mesh filename="meshes/base_of_gripper.obj"/>
      </geometry>
      <material name="">
        <color rgba="0 0 0 0"/>
      </material>
    </visual>
    <collision>
      <origin rpy="0 0 0" xyz="0 0 0"/>
      <geometry>
        <mesh filename="meshes/base_of_gripper.obj"/>
      </geometry>
    </collision>
  </link>

  <!-- tray and object code -->

  <joint name="waiter_tray_joint" type="fixed">
     <origin rpy="0 1.5707 0" xyz="0 -0.14948 0" /> <!-- offset from base of gripper -->
     <parent link="gripper_base" />
     <child link="waiter_tray_link" />
  </joint>

  <link name="waiter_tray_link"> <!-- updated for circular tray -->
    <inertial>
      <origin rpy="0 0 0" xyz="0 -0.144 0" /> <!-- updated for hardware -->
      <mass value="0.354" /> <!-- updated for hardware -->
      <inertia ixx="0.00001806328" ixy="0" ixz="0" iyy="0.00001806328" iyz="0" izz="0.00003596782" /> <!-- updated for hardware -->
    </inertial>
    <visual>
      <origin rpy="0 0 0" xyz="0 0 0"/>
      <geometry>
        <mesh filename="meshes/circ_tray_hardware_shift_scale_v4.obj" /> <!-- need to be updated -->
      </geometry>
      <material name="">
      <color rgba="0.3059 0.2078 0.1412 1" />
      </material>
    </visual>
    <collision>
      <origin rpy="0 0 0" xyz="0 0 0"/>
      <geometry>
        <mesh filename="meshes/circ_tray_hardware_shift_scale_v4.obj" /> <!-- need to be updated -->
      </geometry>
    </collision>
  </link>

  <!-- Joint 10 -->
  <joint name="contact_joint" type="fixed">
     <origin rpy="0 0 0" xyz="0 -0.106 0.002" /> <!-- needs to be updated --> 
     <parent link="waiter_tray_link" />
     <child link="object_link" />
  </joint>

  <link name="object_link">
    <inertial>
      <origin rpy="0 0 0" xyz="0 0 0.0291" /> <!-- updated for hardware -->
      <mass value="0.592" /> <!-- updated for hardware -->
      <inertia ixx="0.00033005074" ixy="0.0" ixz="0.0" iyy="0.00033005074" iyz="0.0" izz="0.00042925501" /> <!-- updated for hardware -->
    </inertial>
    <visual>
      <origin rpy="0 0 0" xyz="0 0 0" />
      <geometry>
        <mesh filename="meshes/cup_hardware_shifted_scaled_rotated.obj" /> <!-- updated for hardware -->
          <!-- scale="0.001 0.001 0.001" -->
      </geometry>
      <material name="">
        <color rgba="0.64 0.64 0.64 1" />
      </material>
    </visual>
    <collision>
      <origin rpy="0 0 0" xyz="0 0 0" />
      <geometry>
        <mesh filename="meshes/cup_hardware_shifted_scaled_rotated.obj" /> <!-- updated for hardware -->
      </geometry>
    </collision>
  </link>


</robot>