<mujoco model="kinova3">
  <actuator>
    <!-- Physical limits of the actuator. Pulled directly from datasheet. See pg 24 of:
         https://www.kinovarobotics.com/sites/default/files/UG-014_KINOVA_Gen3_Ultra_lightweight_robot_User_guide_EN_R06_0.pdf -->
    <motor ctrllimited="true" ctrlrange="-32.0 32.0" joint="Actuator1" name="torq_j1"/>
    <motor ctrllimited="true" ctrlrange="-32.0 32.0" joint="Actuator2" name="torq_j2"/>
    <motor ctrllimited="true" ctrlrange="-32.0 32.0" joint="Actuator3" name="torq_j3"/>
    <motor ctrllimited="true" ctrlrange="-32.0 32.0" joint="Actuator4" name="torq_j4"/>
    <motor ctrllimited="true" ctrlrange="-32.0 32.0" joint="Actuator5" name="torq_j5"/>
    <motor ctrllimited="true" ctrlrange="-13.0 13.0" joint="Actuator6" name="torq_j6"/>
    <motor ctrllimited="true" ctrlrange="-13.0 13.0" joint="Actuator7" name="torq_j7"/>
  </actuator>
  <asset>
    <mesh name="base_link" file="meshes/base_link.stl" />
    <mesh name="shoulder_link" file="meshes/shoulder_link.stl" />
    <mesh name="half_arm_1_link" file="meshes/half_arm_1_link.stl" />
    <mesh name="half_arm_2_link" file="meshes/half_arm_2_link.stl" />
    <mesh name="forearm_link" file="meshes/forearm_link.stl" />
    <mesh name="spherical_wrist_1_link" file="meshes/spherical_wrist_1_link.stl" />
    <mesh name="spherical_wrist_2_link" file="meshes/spherical_wrist_2_link.stl" />
    <mesh name="bracelet_with_vision_link" file="meshes/bracelet_with_vision_link.stl" />
  </asset>
  <worldbody>
    
    <body name="base" pos="0 0 0">
      <!-- robot view -->
      <camera mode="fixed" name="robotview" pos="1.0 0 0.4" quat="0.653 0.271 0.271 0.653"/>
      <inertial diaginertia="0 0 0" mass="1" pos="0 0 0" quat="1 0 0 0"/>
      <!-- mount attached here -->
      <geom type="mesh" contype="0" conaffinity="0" group="1" rgba="1 1 1 1" mesh="base_link" />
      <geom type="mesh" conaffinity="0" rgba="0.75294 0.75294 0.75294 1" mesh="base_link" name="base_collision" />
      
      <body name="shoulder_link" pos="0 0 0.15643" quat="-3.67321e-06 1 0 0">
        <inertial pos="-2.3e-05 -0.010364 -0.07336" quat="0.707051 0.0451246 -0.0453544 0.704263" mass="1.3773" diaginertia="0.00488868 0.00457 0.00135132" />
        <joint name="Actuator1" pos="0 0 0" axis="0 0 1" frictionloss="0.5217383101288284" damping="10.5" armature="8.03"/>
        <geom type="mesh" contype="0" conaffinity="0" group="1" rgba="1 1 1 1" name="s_visual" mesh="shoulder_link" />
        <geom type="mesh" conaffinity="0" rgba="0.75294 0.75294 0.75294 1" mesh="shoulder_link" name="s_collision"/>
        
        <body name="HalfArm1_Link" pos="0 0.005375 -0.12838" quat="0.707105 0.707108 0 0">
          <inertial pos="-4.4e-05 -0.09958 -0.013278" quat="0.482348 0.516286 -0.516862 0.483366" mass="1.1636" diaginertia="0.0113017 0.011088 0.00102532" />
          <joint name="Actuator2" pos="0 0 0" axis="0 0 1" limited="true" range="-2.41 2.41" frictionloss="0.5769579059927288" damping="7.406484581723072" armature="11.996202461530364"/>
          <geom type="mesh" contype="0" conaffinity="0" group="1" rgba="1 1 1 1" name="ha1_visual" mesh="half_arm_1_link" />
          <geom type="mesh" conaffinity="0" rgba="0.75294 0.75294 0.75294 1" mesh="half_arm_1_link" name="ha1_collision"/>
          
          <body name="HalfArm2_Link" pos="0 -0.21038 -0.006375" quat="0.707105 -0.707108 0 0">
            <inertial pos="-4.4e-05 -0.006641 -0.117892" quat="0.706144 0.0213722 -0.0209128 0.707437" mass="1.1636" diaginertia="0.0111633 0.010932 0.00100671" />
            <joint name="Actuator3" pos="0 0 0" axis="0 0 1" frictionloss="0.4213397946418778" damping="9.972763340817286" armature="9.002542786175152"/>
            <geom type="mesh" contype="0" conaffinity="0" group="1" rgba="1 1 1 1" name="ha2_visual" mesh="half_arm_2_link"/>
            <geom type="mesh" conaffinity="0" rgba="0.75294 0.75294 0.75294 1" mesh="half_arm_2_link" name="ha2_collision"/>
            
            <body name="forearm_link" pos="0 0.006375 -0.21038" quat="0.707105 0.707108 0 0">
              <inertial pos="-1.8e-05 -0.075478 -0.015006" quat="0.483678 0.515961 -0.515859 0.483455" mass="0.9302" diaginertia="0.00834839 0.008147 0.000598606" />
              <joint name="Actuator4" pos="0 0 0" axis="0 0 1" limited="true" range="-2.66 2.66" frictionloss="0.4945515376566732" damping="8.266795082250392" armature="11.580643931670636"/>
              <geom type="mesh" contype="0" conaffinity="0" group="1" rgba="1 1 1 1" name="f_visual" mesh="forearm_link" />
              <geom type="mesh" conaffinity="0" rgba="0.75294 0.75294 0.75294 1" mesh="forearm_link" name="f_collision"/>
              
              <body name="SphericalWrist1_Link" pos="0 -0.20843 -0.006375" quat="0.707105 -0.707108 0 0">
                <inertial pos="1e-06 -0.009432 -0.063883" quat="0.703558 0.0707492 -0.0707492 0.703558" mass="0.6781" diaginertia="0.00165901 0.001596 0.000346988" />
                <joint name="Actuator5" pos="0 0 0" axis="0 0 1" frictionloss="0.16110705026613545" damping="8.857224902652815" armature="8.466504091791412"/>
                <geom type="mesh" contype="0" conaffinity="0" group="1" rgba="1 1 1 1" name="w1_visual" mesh="spherical_wrist_1_link" />
                <geom type="mesh" conaffinity="0" rgba="0.75294 0.75294 0.75294 1" mesh="spherical_wrist_1_link" name="w1_collision"/>
                
                <body name="SphericalWrist2_Link" pos="0 0.00017505 -0.10593" quat="0.707105 0.707108 0 0">
                  <inertial pos="1e-06 -0.045483 -0.00965" quat="0.44426 0.550121 -0.550121 0.44426" mass="0.6781" diaginertia="0.00170087 0.001641 0.00035013" />
                  <joint name="Actuator6" pos="0 0 0" axis="0 0 1" limited="true" range="-2.23 2.23" frictionloss="0.13334911855141302" damping="8.711083156933284" armature="8.853706937374243"/>
                  <geom type="mesh" contype="0" conaffinity="0" group="1" rgba="1 1 1 1" name="w2_visual" mesh="spherical_wrist_2_link" />
                  <geom type="mesh" conaffinity="0" rgba="0.75294 0.75294 0.75294 1" mesh="spherical_wrist_2_link" name="w2_collision"/>

                  <body name="Bracelet_Gripper_Tray" pos="0 -0.10593 -0.00017505" euler="-1.5708 0 0">
                    <inertial pos="0.000099 -0.009277 -0.121720" mass="1.45643" fullinertia="0.0273262 4.7262e-8 -1.0167e-5 4.7262e-8 0.026442 5.1493e-4 -1.0167e-5 5.1493e-4 0.0016939"/>
                    <joint name="Actuator7" pos="0 0 0" axis="0 0 1" frictionloss="0.143444018171737" damping="8.888190363830693" armature="8.858730366468532"/>
                    <geom type="mesh" contype="0" conaffinity="0" group="1" rgba="1 1 1 1" name="b_visual" mesh="bracelet_with_vision_link" />
                    <geom type="mesh" conaffinity="0" rgba="0.75294 0.75294 0.75294 1" mesh="bracelet_with_vision_link" name="b_collision"/>
                    
                    <body name="object" pos="0.002 0 -0.371" euler="1.5708 1.5708 0">
                      <inertial pos="0 0 0.0291" mass="0.592" diaginertia="0.00033005074 0.00033005074 0.00042925501"/>
                    </body>
                  </body>
                </body>
              </body>
            </body>
          </body>
        </body>
      </body>
    </body>
  </worldbody>
</mujoco>
